Workbook

Sheet START_HERE
A1: section | B1: details
A2: Scope | B2: Expanded research dataset for mandatory NFL Color Rush promotion, starting in Week 10 of 2015 and ending after 2017.
A3: Game log | B3: Includes 32 game rows: the 4 2015 Color Rush events, 14 2016 TNF games, and 14 2017 Thursday games (including the Thanksgiving 2017 Giants-Washington game, which is not a verified Color Rush game). Home/away and scores were verified against nflverse and corrected. Verify each game's actual uniform use before treating it as a treatment observation.
A4: Critical caveat | B4: The schedule archive includes games in the Color Rush era, but individual teams did not always wear the designed uniform. Use uniform_combo_note and source links to distinguish actual use from scheduled promotion.
A5: Blank values | B5: Blank viewership, sales, social complaint, and broadcaster complaint fields mean not verified / not collected, not zero.
A6: Merchandise | B6: Public Color Rush-specific unit sales and revenue were not found. Do not invent them. Use sales rank or listing price only if documented, and do not treat a rank as sales units.
A7: Analysis plan | B7: First verify actual uniform combos. Then join game-level audience data. Build matched controls based on teams, kickoff slot, network, team strength, star absences, and date. Model viewers as outcome; Color Rush as predictor. Treat estimates as associative unless design supports causality.
A8: Sentiment | B8: Collect public posts using consistent search terms and time windows around game day and policy announcement; deduplicate and manually validate. Do not infer colorblindness unless a person explicitly says so.
A9: Limitations | B9: Game-level Nielsen TV viewership is now sourced for 30 of 32 games (secondary trade-press reporting; networks differ, so compare within network). NFL Shop sales, representative fan surveys, systematic fan-sentiment counts, and on-air broadcaster criticism counts remain unavailable or need independent collection.
A10: Accessibility audit | B10: Accessibility_Audit is pre-populated with all 32 games currently in the game log (linked to the game log); scores are blank until audited. See Audit_Rubric for the 1-5 scale, procedure, calibration anchor, and limitations.
A11: Sentiment collection | B11: Sentiment_Coding is set up for Reddit collection (one row per unique comment, dropdown-validated). See Sentiment_Protocol for rules, Search_Log to record every query, and Reliability_Check for the second-coder subset.

Sheet Game_Log_2015_2017
A1: date | B1: season | C1: week | D1: home_team | E1: away_team | F1: home_score | G1: away_score | H1: network | I1: uniform_combo_note | J1: accessibility_or_context_note | K1: source_note | L1: source_url | M1: viewers_millions | N1: household_rating | O1: audience_metric_source_url | P1: social_complaint_count | Q1: nfl_shop_units_sold | R1: nfl_shop_revenue_usd | S1: broadcast_criticism_count | T1: missing_data_note | U1: score_margin | V1: viewership_basis | W1: tad_millions | X1: viewership_note | Y1: color_rush_status
A2: 2015-11-12 | B2: 2015 | C2: 10 | D2: New York Jets | E2: Buffalo Bills | F2: 17 | G2: 22 | H2: NFL Network | I2: Bills red / Jets green | J2: Documented red-green visibility issue | K2: Gridiron Uniform Database; ABC News | L2: https://www.gridiron-uniforms.com/GUD/controller/controller.php?action=color-rush&page-title=Color+Rush&year=2015 | M2: 7.6 | N2: 4.8 | O2: https://www.sportsmediawatch.com/2017/09/nfl-ratings-2017-49ers-rams-tnf-viewership/ | T2: Merchandise units/revenue: no verified public series. Social complaint and broadcaster complaint counts: not yet collected. Blank is not zero. | U2: 5 | V2: NFL Network only; Nielsen TV | X2: Reported by comparison in a later article. | Y2: Color Rush game
A3: 2015-11-19 | B3: 2015 | C3: 11 | D3: Jacksonville Jaguars | E3: Tennessee Titans | F3: 19 | G3: 13 | H3: NFL Network | I3: Titans blue / Jaguars gold | J3: No verified standardized complaint count | K3: Gridiron Uniform Database | L3: https://www.gridiron-uniforms.com/GUD/controller/controller.php?action=color-rush&page-title=Color+Rush&year=2015 | M3: 6.6 | N3: 4.2 | O3: https://www.sportsmediawatch.com/?p=35494 | T3: Merchandise units/revenue: no verified public series. Social complaint and broadcaster complaint counts: not yet collected. Blank is not zero. | U3: 6 | V3: NFL Network only; Nielsen TV | Y3: Color Rush game
A4: 2015-11-26 | B4: 2015 | C4: 12 | D4: Dallas Cowboys | E4: Carolina Panthers | F4: 14 | G4: 33 | H4: CBS | I4: Panthers blue / Cowboys white | J4: Thanksgiving game; Cowboys used white | K4: Gridiron Uniform Database | L4: https://www.gridiron-uniforms.com/GUD/controller/controller.php?action=color-rush&page-title=Color+Rush&year=2015 | T4: Viewership not located in sources searched. Merchandise units/revenue: no verified public series. Social complaint and broadcaster complaint counts: not yet collected. Blank is not zero. | U4: 19 | X4: Thanksgiving night game on CBS; no sourced figure found. | Y4: Color Rush game
A5: 2015-12-17 | B5: 2015 | C5: 15 | D5: St. Louis Rams | E5: Tampa Bay Buccaneers | F5: 31 | G5: 23 | H5: NFL Network | I5: Buccaneers red / Rams gold | J5: Color-combination criticism often described as ketchup-and-mustard; count not verified | K5: Gridiron Uniform Database | L5: https://www.gridiron-uniforms.com/GUD/controller/controller.php?action=color-rush&page-title=Color+Rush&year=2015 | M5: 6 | N5: 3.8 | O5: https://www.sportsmediawatch.com/2015/12/thursday-night-football-ratings-nfl-network-buccaneers-rams-viewership-season-low/ | T5: Merchandise units/revenue: no verified public series. Social complaint and broadcaster complaint counts: not yet collected. Blank is not zero. | U5: 8 | V5: NFL Network only; Nielsen TV | Y5: Color Rush game
A6: 2016-09-15 | B6: 2016 | C6: 2 | D6: Buffalo Bills | E6: New York Jets | F6: 31 | G6: 37 | H6: CBS / NFL Network / Twitter | I6: Jets white instead of full green; Bills red | J6: Uniform adjustment after 2015 accessibility issue | K6: Gridiron Uniform Database; NFL.com | L6: https://www.gridiron-uniforms.com/GUD/controller/controller.php?action=color-rush&page-title=Color+Rush&year=2016 | M6: 15.4 | N6: 9.5 | O6: https://www.sportsmediawatch.com/2016/09/thursday-night-football-ratings-cbs-nfl-network-twitter-jets-bills-viewership/ | T6: Merchandise units/revenue: no verified public series. Social complaint and broadcaster complaint counts: not yet collected. Blank is not zero. | U6: 6 | V6: CBS + NFL Network; Nielsen TV | W6: 15.7 | X6: TAD 15.7M is AP's all-platform per-minute average incl. Twitter. | Y6: Color Rush game
A7: 2016-09-22 | B7: 2016 | C7: 3 | D7: New England Patriots | E7: Houston Texans | F7: 27 | G7: 0 | H7: CBS / NFL Network / Twitter | I7: Texans / Patriots Color Rush | J7: No verified standardized complaint count | K7: Gridiron Uniform Database | L7: https://www.gridiron-uniforms.com/GUD/controller/controller.php?action=color-rush&page-title=Color+Rush&year=2016 | M7: 17.5 | N7: 10.6 | O7: https://www.sportsmediawatch.com/2017/09/nfl-ratings-2017-49ers-rams-tnf-viewership/ | T7: Merchandise units/revenue: no verified public series. Social complaint and broadcaster complaint counts: not yet collected. Blank is not zero. | U7: 27 | V7: CBS + NFL Network; Nielsen TV | X7: Reported by comparison in a later article. | Y7: Color Rush game
A8: 2016-09-29 | B8: 2016 | C8: 4 | D8: Cincinnati Bengals | E8: Miami Dolphins | F8: 22 | G8: 7 | H8: NFL Network | I8: Dolphins / Bengals Color Rush | J8: No verified standardized complaint count | K8: Gridiron Uniform Database | L8: https://www.gridiron-uniforms.com/GUD/controller/controller.php?action=color-rush&page-title=Color+Rush&year=2016 | M8: 7.9 | N8: 4.8 | O8: https://www.sportsmediawatch.com/2016/09/thursday-night-football-ratings-nfl-network-dolphins-bengals-viewership/ | T8: Merchandise units/revenue: no verified public series. Social complaint and broadcaster complaint counts: not yet collected. Blank is not zero. | U8: 15 | V8: NFL Network only; Nielsen TV | W8: 8 | X8: NFL press release (streamingmedia.com) gave 4.76 HH / 8.0M incl. digital. | Y8: Color Rush game
A9: 2016-10-06 | B9: 2016 | C9: 5 | D9: San Francisco 49ers | E9: Arizona Cardinals | F9: 21 | G9: 33 | H9: CBS / NFL Network / Twitter | I9: Cardinals / 49ers Color Rush | J9: No verified standardized complaint count | K9: Gridiron Uniform Database | L9: https://www.gridiron-uniforms.com/GUD/controller/controller.php?action=color-rush&page-title=Color+Rush&year=2016 | M9: 12.1 | N9: 7.4 | O9: https://www.sportsmediawatch.com/2016/10/thursday-night-football-ratings-down-cbs-49ers-cardinals-viewership/ | S9: 1 | T9: Merchandise units/revenue: no verified public series. Social complaint and broadcaster complaint counts: not yet collected. Blank is not zero. | U9: 12 | V9: CBS + NFL Network; Nielsen TV | X9: Later SMW articles cite 12.07M. | Y9: Color Rush game
A10: 2016-10-13 | B10: 2016 | C10: 6 | D10: San Diego Chargers | E10: Denver Broncos | F10: 21 | G10: 13 | H10: CBS / NFL Network / Twitter | I10: Broncos / Chargers Color Rush | J10: No verified standardized complaint count | K10: Gridiron Uniform Database | L10: https://www.gridiron-uniforms.com/GUD/controller/controller.php?action=color-rush&page-title=Color+Rush&year=2016 | M10: 14.5 | N10: 8.7 | O10: https://www.sportsmediawatch.com/2017/10/thursday-night-football-ratings-week-seven-chiefs-raiders/ | T10: Merchandise units/revenue: no verified public series. Social complaint and broadcaster complaint counts: not yet collected. Blank is not zero. | U10: 8 | V10: CBS + NFL Network; Nielsen TV | X10: Later SMW article cites 14.49M. | Y10: Color Rush game
A11: 2016-10-20 | B11: 2016 | C11: 7 | D11: Green Bay Packers | E11: Chicago Bears | F11: 26 | G11: 10 | H11: CBS / NFL Network / Twitter | I11: Bears / Packers Color Rush | J11: No verified standardized complaint count | K11: Gridiron Uniform Database | L11: https://www.gridiron-uniforms.com/GUD/controller/controller.php?action=color-rush&page-title=Color+Rush&year=2016 | M11: 14.2 | N11: 8.6 | O11: https://www.sportsmediawatch.com/2017/09/nfl-ratings-2017-thursday-night-football-cbs-bears-packers/ | T11: Merchandise units/revenue: no verified public series. Social complaint and broadcaster complaint counts: not yet collected. Blank is not zero. | U11: 16 | V11: CBS + NFL Network; Nielsen TV | X11: Reported by comparison in a later article. | Y11: Color Rush game
A12: 2016-10-27 | B12: 2016 | C12: 8 | D12: Tennessee Titans | E12: Jacksonville Jaguars | F12: 36 | G12: 22 | H12: NFL Network | I12: Jaguars / Titans Color Rush | J12: No verified standardized complaint count | K12: Gridiron Uniform Database | L12: https://www.gridiron-uniforms.com/GUD/controller/controller.php?action=color-rush&page-title=Color+Rush&year=2016 | M12: 5.1 | N12: 3.2 | O12: https://www.sportsmediawatch.com/?p=43603 | T12: Merchandise units/revenue: no verified public series. Social complaint and broadcaster complaint counts: not yet collected. Blank is not zero. | U12: 14 | V12: NFL Network only; Nielsen TV | X12: Rating from a later SMW comparison (2017 49ers-Rams article). | Y12: Color Rush game
A13: 2016-11-03 | B13: 2016 | C13: 9 | D13: Tampa Bay Buccaneers | E13: Atlanta Falcons | F13: 28 | G13: 43 | H13: NFL Network | I13: Falcons / Buccaneers Color Rush | J13: No verified standardized complaint count | K13: Gridiron Uniform Database | L13: https://www.gridiron-uniforms.com/GUD/controller/controller.php?action=color-rush&page-title=Color+Rush&year=2016 | M13: 5.844 | N13: 3.6 | O13: https://www.sportsmediawatch.com/?p=53610 | T13: Merchandise units/revenue: no verified public series. Social complaint and broadcaster complaint counts: not yet collected. Blank is not zero. | U13: 15 | V13: NFL Network only; Nielsen TV | X13: Reported only by comparison in a 2017 article; no direct 2016 source found. | Y13: Color Rush game
A14: 2016-11-10 | B14: 2016 | C14: 10 | D14: Baltimore Ravens | E14: Cleveland Browns | F14: 28 | G14: 7 | H14: NFL Network | I14: Browns / Ravens Color Rush | J14: No verified standardized complaint count | K14: Gridiron Uniform Database | L14: https://www.gridiron-uniforms.com/GUD/controller/controller.php?action=color-rush&page-title=Color+Rush&year=2016 | M14: 5.7 | N14: 3.5 | O14: https://www.sportsmediawatch.com/2016/11/thursday-night-football-ratings-nfl-network-browns-ravens-viewership/ | T14: Merchandise units/revenue: no verified public series. Social complaint and broadcaster complaint counts: not yet collected. Blank is not zero. | U14: 21 | V14: NFL Network only; Nielsen TV | Y14: Color Rush game
A15: 2016-11-17 | B15: 2016 | C15: 11 | D15: Carolina Panthers | E15: New Orleans Saints | F15: 23 | G15: 20 | H15: NBC / NFL Network / Twitter | I15: Saints / Panthers Color Rush | J15: No verified standardized complaint count | K15: Gridiron Uniform Database | L15: https://www.gridiron-uniforms.com/GUD/controller/controller.php?action=color-rush&page-title=Color+Rush&year=2016 | M15: 13.3 | N15: 8.1 | O15: https://www.sportsmediawatch.com/2016/11/thursday-night-football-ratings-nbc-panthers-saints-nfl-network-viewership/ | T15: Merchandise units/revenue: no verified public series. Social complaint and broadcaster complaint counts: not yet collected. Blank is not zero. | U15: 3 | V15: NBC + NFL Network; Nielsen TV | W15: 13.6 | X15: TAD per NBC release (incl. Twitter, NBC/NFL digital). | Y15: Color Rush game
A16: 2016-12-01 | B16: 2016 | C16: 13 | D16: Minnesota Vikings | E16: Dallas Cowboys | F16: 15 | G16: 17 | H16: NBC / NFL Network / Twitter | I16: Cowboys / Vikings Color Rush | J16: No verified standardized complaint count | K16: Gridiron Uniform Database | L16: https://www.gridiron-uniforms.com/GUD/controller/controller.php?action=color-rush&page-title=Color+Rush&year=2016 | M16: 21.8 | N16: 12.8 | O16: https://nbcsportsgrouppressbox.com/2016/12/02/cowboys-vikings-on-nbc-nfl-network-twitter-is-most-watched-thursday-night-football-game-ever/ | T16: Merchandise units/revenue: no verified public series. Social complaint and broadcaster complaint counts: not yet collected. Blank is not zero. | U16: 2 | V16: NBC + NFL Network; Nielsen TV | W16: 22.2 | X16: Most-watched TNF game to that point. Rating 12.8 from a later SMW article. | Y16: Color Rush game
A17: 2016-12-08 | B17: 2016 | C17: 14 | D17: Kansas City Chiefs | E17: Oakland Raiders | F17: 21 | G17: 13 | H17: NBC / NFL Network / Twitter | I17: Raiders / Chiefs Color Rush | J17: No verified standardized complaint count | K17: Gridiron Uniform Database | L17: https://www.gridiron-uniforms.com/GUD/controller/controller.php?action=color-rush&page-title=Color+Rush&year=2016 | M17: 17.4 | N17: 10.5 | O17: https://nbcsportsgrouppressbox.com/2016/12/09/raiders-chiefs-on-nbc-nfl-network-twitter-posts-thursday-night-football-total-audience-delivery-average-of-17-8-million-viewers/ | T17: Merchandise units/revenue: no verified public series. Social complaint and broadcaster complaint counts: not yet collected. Blank is not zero. | U17: 8 | V17: NBC + NFL Network; Nielsen TV | W17: 17.8 | X17: Rating 10.5 from a later SMW article. | Y17: Color Rush game
A18: 2016-12-15 | B18: 2016 | C18: 15 | D18: Seattle Seahawks | E18: Los Angeles Rams | F18: 24 | G18: 3 | H18: NBC / NFL Network / Twitter | I18: Rams / Seahawks Color Rush | J18: No verified standardized complaint count | K18: Gridiron Uniform Database | L18: https://www.gridiron-uniforms.com/GUD/controller/controller.php?action=color-rush&page-title=Color+Rush&year=2016 | M18: 14.65 | N18: 8.8 | O18: https://www.sportsmediawatch.com/?p=44590 | T18: Merchandise units/revenue: no verified public series. Social complaint and broadcaster complaint counts: not yet collected. Blank is not zero. | U18: 21 | V18: NBC + NFL Network; Nielsen TV | X18: Initial report said 14.6M; later SMW cites 14.65M. Twitter added 321K. | Y18: Color Rush game
A19: 2016-12-22 | B19: 2016 | C19: 16 | D19: Philadelphia Eagles | E19: New York Giants | F19: 24 | G19: 19 | H19: NBC / NFL Network / Twitter | I19: Giants / Eagles Color Rush | J19: No verified standardized complaint count | K19: Gridiron Uniform Database | L19: https://www.gridiron-uniforms.com/GUD/controller/controller.php?action=color-rush&page-title=Color+Rush&year=2016 | M19: 17.9 | O19: https://www.sportsvideo.org/2016/12/27/ratings-roundup-snf-tnf-are-top-two-fall-primetime-shows-abcs-nba-finals-rematch-pulls-in-big-numbers-on-christmas/ | T19: Merchandise units/revenue: no verified public series. Social complaint and broadcaster complaint counts: not yet collected. Blank is not zero. | U19: 5 | V19: NBC + NFL Network; Nielsen TV | W19: 18.3 | X19: Household rating not found. | Y19: Color Rush game
A20: 2017-09-14 | B20: 2017 | C20: 2 | D20: Cincinnati Bengals | E20: Houston Texans | F20: 9 | G20: 13 | H20: NFL Network | I20: Texans / Bengals Color Rush | J20: No verified standardized complaint count | K20: Gridiron Uniform Database; Sports Illustrated | L20: https://www.gridiron-uniforms.com/GUD/controller/controller.php?action=color-rush&page-title=Color+Rush&year=2017 | M20: 8.1 | N20: 4.9 | O20: https://www.sportsmediawatch.com/2017/09/nfl-ratings-2017-thursday-night-football-bengals-texans-viewership/ | T20: Merchandise units/revenue: no verified public series. Social complaint and broadcaster complaint counts: not yet collected. Blank is not zero. | U20: 4 | V20: NFL Network only; Nielsen TV | Y20: Color Rush game
A21: 2017-09-21 | B21: 2017 | C21: 3 | D21: San Francisco 49ers | E21: Los Angeles Rams | F21: 39 | G21: 41 | H21: NFL Network | I21: Rams / 49ers Color Rush | J21: Close game; no verified standardized complaint count | K21: Gridiron Uniform Database; Sports Illustrated | L21: https://www.gridiron-uniforms.com/GUD/controller/controller.php?action=color-rush&page-title=Color+Rush&year=2017 | M21: 7.4 | N21: 4.4 | O21: https://www.sportsmediawatch.com/2017/09/nfl-ratings-2017-49ers-rams-tnf-viewership/ | T21: Merchandise units/revenue: no verified public series. Social complaint and broadcaster complaint counts: not yet collected. Blank is not zero. | U21: 2 | V21: NFL Network only; Nielsen TV | Y21: Color Rush game
A22: 2017-09-28 | B22: 2017 | C22: 4 | D22: Green Bay Packers | E22: Chicago Bears | F22: 35 | G22: 14 | H22: CBS / NFL Network / Amazon Prime | I22: Bears / Packers Color Rush | J22: No verified standardized complaint count | K22: Gridiron Uniform Database; Sports Illustrated | L22: https://www.gridiron-uniforms.com/GUD/controller/controller.php?action=color-rush&page-title=Color+Rush&year=2017 | M22: 14.6 | N22: 8.9 | O22: https://www.sportsmediawatch.com/2017/09/nfl-ratings-2017-thursday-night-football-cbs-bears-packers/ | T22: Merchandise units/revenue: no verified public series. Social complaint and broadcaster complaint counts: not yet collected. Blank is not zero. | U22: 21 | V22: CBS + NFL Network; Nielsen TV | Y22: Color Rush game
A23: 2017-10-05 | B23: 2017 | C23: 5 | D23: Tampa Bay Buccaneers | E23: New England Patriots | F23: 14 | G23: 19 | H23: CBS / NFL Network / Amazon Prime | I23: Patriots / Buccaneers Color Rush | J23: No verified standardized complaint count | K23: Gridiron Uniform Database; Sports Illustrated | L23: https://www.gridiron-uniforms.com/GUD/controller/controller.php?action=color-rush&page-title=Color+Rush&year=2017 | M23: 15.4 | N23: 9.4 | O23: https://www.sportsmediawatch.com/?p=52567 | T23: Merchandise units/revenue: no verified public series. Social complaint and broadcaster complaint counts: not yet collected. Blank is not zero. | U23: 5 | V23: CBS + NFL Network; Nielsen TV | Y23: Color Rush game
A24: 2017-10-12 | B24: 2017 | C24: 6 | D24: Carolina Panthers | E24: Philadelphia Eagles | F24: 23 | G24: 28 | H24: CBS / NFL Network / Amazon Prime | I24: Eagles / Panthers Color Rush | J24: No verified standardized complaint count | K24: Gridiron Uniform Database; Sports Illustrated | L24: https://www.gridiron-uniforms.com/GUD/controller/controller.php?action=color-rush&page-title=Color+Rush&year=2017 | M24: 14.59 | N24: 8.9 | O24: https://www.sportsmediawatch.com/2018/10/thursday-night-football-ratings-giants-eagles/ | T24: Merchandise units/revenue: no verified public series. Social complaint and broadcaster complaint counts: not yet collected. Blank is not zero. | U24: 5 | V24: CBS + NFL Network; Nielsen TV | X24: Reported by comparison in a 2018 article. | Y24: Color Rush game
A25: 2017-10-19 | B25: 2017 | C25: 7 | D25: Oakland Raiders | E25: Kansas City Chiefs | F25: 31 | G25: 30 | H25: CBS / NFL Network / Amazon Prime | I25: Chiefs / Raiders Color Rush | J25: Close game; no verified standardized complaint count | K25: Gridiron Uniform Database; Sports Illustrated | L25: https://www.gridiron-uniforms.com/GUD/controller/controller.php?action=color-rush&page-title=Color+Rush&year=2017 | M25: 14.4 | N25: 8.6 | O25: https://www.sportsmediawatch.com/2017/10/thursday-night-football-ratings-week-seven-chiefs-raiders/ | T25: Merchandise units/revenue: no verified public series. Social complaint and broadcaster complaint counts: not yet collected. Blank is not zero. | U25: 1 | V25: CBS + NFL Network; Nielsen TV | Y25: Color Rush game
A26: 2017-10-26 | B26: 2017 | C26: 8 | D26: Baltimore Ravens | E26: Miami Dolphins | F26: 40 | G26: 0 | H26: CBS / NFL Network / Amazon Prime | I26: Dolphins / Ravens Color Rush | J26: Blowout; no verified standardized complaint count | K26: Gridiron Uniform Database; Sports Illustrated | L26: https://www.gridiron-uniforms.com/GUD/controller/controller.php?action=color-rush&page-title=Color+Rush&year=2017 | M26: 11.4 | N26: 7 | O26: https://www.sportsmediawatch.com/?p=53379 | T26: Merchandise units/revenue: no verified public series. Social complaint and broadcaster complaint counts: not yet collected. Blank is not zero. | U26: 40 | V26: CBS + NFL Network; Nielsen TV | X26: Lowest-rated TNF game to that point (40-point blowout). | Y26: Color Rush game
A27: 2017-11-02 | B27: 2017 | C27: 9 | D27: New York Jets | E27: Buffalo Bills | F27: 34 | G27: 21 | H27: NFL Network | I27: Bills / Jets Color Rush | J27: Red-green matchup avoided after 2015 controversy; exact uniform combo should be confirmed | K27: Gridiron Uniform Database; Sports Illustrated | L27: https://www.gridiron-uniforms.com/GUD/controller/controller.php?action=color-rush&page-title=Color+Rush&year=2017 | M27: 5.844 | N27: 3.6 | O27: https://www.sportsmediawatch.com/?p=53610 | T27: Merchandise units/revenue: no verified public series. Social complaint and broadcaster complaint counts: not yet collected. Blank is not zero. | U27: 13 | V27: NFL Network only; Nielsen TV | Y27: Color Rush game
A28: 2017-11-09 | B28: 2017 | C28: 10 | D28: Arizona Cardinals | E28: Seattle Seahawks | F28: 16 | G28: 22 | H28: NBC / NFL Network / Amazon Prime | I28: Seahawks / Cardinals Color Rush | J28: No verified standardized complaint count | K28: Gridiron Uniform Database; Sports Illustrated | L28: https://www.gridiron-uniforms.com/GUD/controller/controller.php?action=color-rush&page-title=Color+Rush&year=2017 | M28: 13.1 | N28: 7.9 | O28: https://www.sportsmediawatch.com/?p=61359 | T28: Merchandise units/revenue: no verified public series. Social complaint and broadcaster complaint counts: not yet collected. Blank is not zero. | U28: 6 | V28: NBC + NFL Network; Nielsen TV | X28: Reported by comparison in a 2018 article. | Y28: Color Rush game
A29: 2017-11-16 | B29: 2017 | C29: 11 | D29: Pittsburgh Steelers | E29: Tennessee Titans | F29: 40 | G29: 17 | H29: NBC / NFL Network / Amazon Prime | I29: Titans / Steelers Color Rush | J29: No verified standardized complaint count | K29: Gridiron Uniform Database; Sports Illustrated | L29: https://www.gridiron-uniforms.com/GUD/controller/controller.php?action=color-rush&page-title=Color+Rush&year=2017 | M29: 13.5 | N29: 8.2 | O29: https://www.sportsmediawatch.com/?p=53929 | T29: Merchandise units/revenue: no verified public series. Social complaint and broadcaster complaint counts: not yet collected. Blank is not zero. | U29: 23 | V29: NBC + NFL Network; Nielsen TV | X29: Streaming added 409K (Amazon, NBC/NFL digital). | Y29: Color Rush game
A30: 2017-11-23 | B30: 2017 | C30: 12 | D30: Washington Redskins | E30: New York Giants | F30: 20 | G30: 10 | H30: FOX / NFL Network | I30: Giants / Washington alternate combination | J30: Thanksgiving; Washington did not wear the originally designed gold Color Rush set | K30: Gridiron Uniform Database; Sports Illustrated | L30: https://www.gridiron-uniforms.com/GUD/controller/controller.php?action=color-rush&page-title=Color+Rush&year=2017 | T30: Viewership not located in sources searched. Merchandise units/revenue: no verified public series. Social complaint and broadcaster complaint counts: not yet collected. Blank is not zero. | U30: 10 | X30: Thanksgiving night game on FOX; not a TNF simulcast. No sourced figure found. | Y30: Thanksgiving: exempt from Color Rush per Wikipedia (2016 policy); not verified as a Color Rush game. Treat as non-treatment/control unless uniforms are verified.
A31: 2017-11-30 | B31: 2017 | C31: 13 | D31: Dallas Cowboys | E31: Washington Redskins | F31: 38 | G31: 14 | H31: CBS / NFL Network / Amazon Prime | I31: Washington / Cowboys Color Rush | J31: Washington's intended design was not used; code actual uniforms separately | K31: Gridiron Uniform Database; Sports Illustrated | L31: https://www.gridiron-uniforms.com/GUD/controller/controller.php?action=color-rush&page-title=Color+Rush&year=2017 | M31: 15.6 | N31: 9.4 | O31: https://www.sportsmediawatch.com/?p=61628 | T31: Merchandise units/revenue: no verified public series. Social complaint and broadcaster complaint counts: not yet collected. Blank is not zero. | U31: 24 | V31: CBS + NFL Network; Nielsen TV | X31: Reported by comparison in a 2018 article; network per that article is a TNF simulcast. | Y31: Color Rush game; Washington declined the gold design and wore all-burgundy (Wikipedia).
A32: 2017-12-07 | B32: 2017 | C32: 14 | D32: Atlanta Falcons | E32: New Orleans Saints | F32: 20 | G32: 17 | H32: NBC / NFL Network / Amazon Prime | I32: Saints / Falcons Color Rush | J32: No verified standardized complaint count | K32: Gridiron Uniform Database; Sports Illustrated | L32: https://www.gridiron-uniforms.com/GUD/controller/controller.php?action=color-rush&page-title=Color+Rush&year=2017 | M32: 14.61 | N32: 8.9 | O32: https://www.sportsmediawatch.com/?p=54300 | T32: Merchandise units/revenue: no verified public series. Social complaint and broadcaster complaint counts: not yet collected. Blank is not zero. | U32: 3 | V32: NBC + NFL Network; Nielsen TV | Y32: Color Rush game
A33: 2017-12-14 | B33: 2017 | C33: 15 | D33: Indianapolis Colts | E33: Denver Broncos | F33: 13 | G33: 25 | H33: NBC / NFL Network / Amazon Prime | I33: Broncos / Colts Color Rush | J33: No verified standardized complaint count | K33: Gridiron Uniform Database; Sports Illustrated | L33: https://www.gridiron-uniforms.com/GUD/controller/controller.php?action=color-rush&page-title=Color+Rush&year=2017 | M33: 10.64 | N33: 6.5 | O33: https://www.sportsmediawatch.com/?p=61359 | T33: Merchandise units/revenue: no verified public series. Social complaint and broadcaster complaint counts: not yet collected. Blank is not zero. | U33: 12 | V33: NBC + NFL Network; Nielsen TV | X33: Then among the lowest-rated broadcast primetime NFL games. | Y33: Color Rush game

Sheet Viewership_Context
A1: season | B1: metric | C1: viewers_millions | D1: household_rating | E1: scope_caveat | F1: source_url
A2: 2015 | B2: TNF season opener: Broncos-Chiefs | C2: 21.1 | D2: 12.9 | E2: Single game; not Color Rush causal evidence | F2: https://www.nfl.com/news/thursday-night-football-sets-high-mark-for-viewership-ratings-0ap3000000533601
A3: 2015 | B3: TNF package average | C3: 12.425 | E3: Package-wide average; not Color Rush-only | F3: https://www.sportsbusinessjournal.com/Daily/Issues/2017/12/29/Media/NFL-primetime/
A4: 2016 | B4: TNF package average | C4: 12.438 | E4: Package-wide average; not Color Rush-only | F4: https://www.sportsbusinessjournal.com/Daily/Issues/2017/12/29/Media/NFL-primetime/
A5: 2017 | B5: TNF package average | C5: 10.937 | E5: Package-wide average; not Color Rush-only | F5: https://www.sportsbusinessjournal.com/Daily/Issues/2017/12/29/Media/NFL-primetime/
A6: 2016 | B6: CBS five-game TNF average (TV) | C6: 14.7 | E6: Package-wide; not Color Rush-only | F6: https://www.bangordailynews.com/2016/12/24/sports/nbc-ends-thursday-night-football-on-high-note/
A7: 2016 | B7: NBC five-game TNF average (TV-only) | C7: 17 | E7: Package-wide; TAD incl. Twitter/digital was 17.4M | F7: https://www.sportsvideo.org/2016/12/27/ratings-roundup-snf-tnf-are-top-two-fall-primetime-shows-abcs-nba-finals-rematch-pulls-in-big-numbers-on-christmas/
A8: 2016 | B8: NFL Network-exclusive games, rating/viewers range (3 games: Jaguars-Titans 5.1M, Browns-Ravens 5.7M, Falcons-Bucs ~5.8M; Dolphins-Bengals 7.9M) | E8: Game-level figures are on Game_Log_2015_2017; do not compare across networks without controls | F8: https://www.sportsmediawatch.com/2016/11/thursday-night-football-ratings-nfl-network-browns-ravens-viewership/

Sheet Evidence_Claims
A1: topic | B1: finding | C1: confidence | D1: source_url
A2: Accessibility backlash | B2: 2015 Bills-Jets red/green uniforms caused documented confusion for viewers with red-green color vision deficiency. | C2: High | D2: https://abcnews.com/Sports/blind-rush-nfls-color-rush-jerseys-problematic-colorblind/story?id=35169972
A3: NFL response | B3: NFL acknowledged a need to improve color-blind testing; later Bills-Jets matchup used adjusted uniforms. | C3: High | D3: https://www.nfl.com/news/jets-bills-will-get-color-rush-do-over-in-week-2-0ap3000000653520
A4: Promotion ended | B4: Mandatory TNF Color Rush promotion ended after 2017; teams could keep wearing the designs as alternates. | C4: High | D4: https://www.si.com/nfl/2018/09/14/what-happened-color-rush-uniforms-nfl-thursday-night
A5: Broadcast strategy | B5: FOX's TNF approach emphasized matchups and a new broadcast presentation; public reporting does not establish Color Rush as a direct cause of ratings decline. | C5: High | D5: https://www.thescore.com/nfl/news/1524879/fox-scrapping-tnf-color-rush-working-to-improve-matchups
A6: Viewership trend | B6: TNF package average audience fell from 12.438M in 2016 to 10.937M in 2017 (about -12.1%). This is package-level context, not causal evidence. | C6: High for package totals | D6: https://www.sportsbusinessjournal.com/Daily/Issues/2017/12/29/Media/NFL-primetime/
A7: Merchandise fundraising | B7: Seahawks/NFL team release stated NFL proceeds from Color Rush jersey sales went to the NFL Foundation; this is not a sales volume measure. | C7: High for stated policy | D7: https://www.seahawks.com/news/seattle-seahawks-unveil-action-green-color-rush-uniform-167051
A8: Merchandise sales gap | B8: No verified public game-by-game Color Rush unit sales/revenue series was found in the sources used for this workbook. | C8: High as research limitation | D8: https://nflpa.com/partners/posts/things-to-know-about-the-2025-year-end-nflpa-top-50-player-sales-list
A9: Player criticism | B9: Jaguars QB Blake Bortles publicly criticized the team's Color Rush uniforms; anecdotal, not representative survey data. | C9: High that reported; anecdotal | D9: https://www.foxsports.com/stories/other/blake-bortles-calls-jaguars-color-rush-uniforms-ugly-as-hell
A10: Game-level viewership | B10: Sourced Nielsen TV viewers and household ratings were added for 30 of 32 games (all except the 2015 Thanksgiving Panthers-Cowboys and 2017 Thanksgiving Giants-Washington games). Network matters: NFL Network-only games drew roughly 5-8M, simulcast games roughly 10-22M, so uniform effects cannot be read off raw viewership. | C10: Medium-High (secondary trade-press reporting of Nielsen) | D10: https://www.sportsmediawatch.com/?p=53929
A11: Data correction | B11: Cross-check against nflverse games.csv showed the original game log had home and away teams swapped on all 32 rows, the 2017-10-19 Chiefs-Raiders score reversed (Raiders won 31-30), and the 2017-11-30 Washington score wrong (14, not 6). These are corrected. | C11: High (two independent sources for 2015: AP and nflverse) | D11: https://raw.githubusercontent.com/nflverse/nfldata/master/data/games.csv
A12: Thanksgiving exemption | B12: Thanksgiving games were exempt from the Color Rush promotion from 2016, so the 2017-11-23 row is not a verified Color Rush game. | C12: Medium-High | D12: https://en.wikipedia.org/wiki/Color_Rush
... A18: Fox ended the promotion | B18: Fox Sports' Bill Wanger told Barrett Sports Media on April 10, 2018 that Color Rush would not be on Thursday Night Football; the NFL's Mike Garafolo said teams could keep them as alternates. | C18: High (April 10, 2018 reports) | D18: https://www.thescore.com/news/1524879

Sheet Sources
A1: publisher | B1: source_topic | C1: url
A2: Gridiron Uniform Database | B2: 2015 Color Rush game archive | C2: https://www.gridiron-uniforms.com/GUD/controller/controller.php?action=color-rush&page-title=Color+Rush&year=2015
A3: Gridiron Uniform Database | B3: 2016 Color Rush game archive | C3: https://www.gridiron-uniforms.com/GUD/controller/controller.php?action=color-rush&page-title=Color+Rush&year=2016
A4: Gridiron Uniform Database | B4: 2017 Color Rush game archive | C4: https://www.gridiron-uniforms.com/GUD/controller/controller.php?action=color-rush&page-title=Color+Rush&year=2017
A5: NFL.com | B5: 2017 Color Rush uniform gallery | C5: https://www.nfl.com/photos/2017-nfl-color-rush-0ap3000000844763
A6: Sports Illustrated | B6: 2017 TNF schedule and Color Rush uniforms | C6: https://www.si.com/nfl/2017/09/14/nfl-color-rush-uniforms-jerseys-thursday-night-football
A7: ABC News | B7: 2015 colorblind accessibility complaints | C7: https://abcnews.com/Sports/blind-rush-nfls-color-rush-jerseys-problematic-colorblind/story?id=35169972
A8: NFL.com | B8: NFL response to Bills-Jets uniform issue | C8: https://www.nfl.com/news/jets-bills-will-get-color-rush-do-over-in-week-2-0ap3000000653520
A9: Sports Business Journal | B9: TNF audience trend | C9: https://www.sportsbusinessjournal.com/Daily/Issues/2017/12/29/Media/NFL-primetime/
A10: theScore | B10: FOX decision and broadcast strategy | C10: https://www.thescore.com/nfl/news/1524879/fox-scrapping-tnf-color-rush-working-to-improve-matchups
A11: Seattle Seahawks | B11: Color Rush jersey proceeds policy | C11: https://www.seahawks.com/news/seattle-seahawks-unveil-action-green-color-rush-uniform-167051
A12: FOX Sports | B12: Blake Bortles reaction | C12: https://www.foxsports.com/stories/other/blake-bortles-calls-jaguars-color-rush-uniforms-ugly-as-hell
... A24: theScore | B24: April 10, 2018 report on Color Rush ending | C24: https://www.thescore.com/news/1524879

Sheet Sentiment_Coding
A1: record_id | B1: record_type | C1: platform | D1: created_utc | E1: subreddit | F1: thread_id | G1: game_id | H1: retrospective_flag | I1: search_query | J1: source_url | K1: relevance | L1: sentiment | M1: aesthetic_dislike | N1: accessibility_concern | O1: explicit_colorblind_reference | P1: broadcast_complaint | Q1: merchandise_opinion | R1: program_cancellation_opinion | S1: criticism_target | T1: evidence_excerpt | U1: duplicate_flag | V1: double_coded | W1: coder_id | X1: coding_confidence | Y1: notes | Z1: pilot_stratum

Sheet Search_Log
A1: query_id | B1: date_run | C1: source | D1: exact_query | E1: subreddit_filter | F1: date_range_filter | G1: results_returned | H1: records_reviewed | I1: records_included | J1: notes

Sheet Reliability_Check
A1: record_id | B1: coder_1_id | C1: coder_2_id | D1: sentiment_1 | E1: sentiment_2 | F1: accessibility_concern_1 | G1: accessibility_concern_2 | H1: notes

Sheet Sentiment_Protocol
A1: section | B1: details
A2: Research question | B2: How did Reddit users react to Color Rush uniforms in 2015-2017, and how much of the criticism concerned accessibility vs. aesthetics?
A3: Window | B3: 2015-09-01 to 2017-12-31. Later retrospective posts are allowed only with retrospective_flag = 1 and analyzed separately.
A4: Sources | B4: Reddit search (current results only), Arctic Shift (archived submissions/comments), Wayback Machine. Archive coverage is incomplete: log every query, source, and run date on Search_Log. Missing posts are not evidence that fans did not care.
A5: Search terms | B5: Program: "Color Rush", "Color Rush uniforms", "Thursday Night Football uniforms". Accessibility: colorblind, colourblind, "color blind", "red green". Dislike: "ugly uniforms", "worst uniforms", jerseys. Teams: "all red", "all green", "Jets Bills uniforms". Broadcast: "Color Rush" broadcast / announcer / TV. Terms like "Bills Jets" are noisy: confirm relevance manually. Run each query separately and save it exactly.
A6: Include | B6: Discusses Color Rush uniforms, their look, visibility, or the program; mentions colorblindness or difficulty telling teams apart; criticizes design or broadcast presentation as it relates to Color Rush; inside the window (or retrospective, flagged).
A7: Exclude | B7: Unrelated team-uniform talk; duplicate copies; bots/spam/uninterpretable text; pure game talk with no uniform or broadcast content. Excluded records may be logged with relevance = exclude, or counted on Search_Log.
A8: Unit of analysis | B8: One row per unique comment. Submissions are record_type = submission and analyzed separately so one popular thread is not counted as one comment. Report both comment counts and distinct-thread counts.
A9: Coding rules | B9: Theme flags are independent 0/1 (a comment can be both aesthetic_dislike and accessibility_concern). accessibility_concern = 1 for a stated difficulty telling teams apart or a colorblindness complaint. explicit_colorblind_reference = 1 only if the person explicitly mentions colorblindness or CVD; never infer it. Keep ambiguous rows as relevance = uncertain / coding_confidence = low rather than forcing a category.
A10: Coding examples (hypothetical) | B10: "Those jerseys are ugly." -> negative, aesthetic 1, accessibility 0. "I can't tell the red and green teams apart on TV." -> negative, accessibility 1, explicit_colorblind 0. "I'm colorblind, and the Bills-Jets game was impossible to follow." -> negative, accessibility 1, explicit_colorblind 1. "The bright uniforms look great under the lights." -> positive, all flags 0.
A11: game_id | B11: Use IDs from Accessibility_Audit (G01-G32, in game-log order) so sentiment joins to the audit. Leave blank if the game is not identifiable.
A12: Pilot first | B12: Collect 50-100 relevant comments first. Check that queries retrieve useful material, categories work, and accessibility complaints appear often enough to analyze. Then expand under the same fixed rules.
... A17: Pilot sampling | B17: Stages: (1) search test of 8-12 queries logged on Search_Log; (2) collect 50-100 relevant 2015-2017 comments across multiple games; (3) flag duplicates and cross-posts; (4) code all eligible records; (5) second coder on 10-20 records; (6) evaluate noisy queries, missing games, and hard-to-separate categories. Sample in three strata (pilot_stratum): A_bills_jets_2015, B_other_games, C_general_program, so the Bills-Jets controversy cannot stand in for broad sentiment. Cap eligible comments per thread (Pilot_Tally!B5). Record denominators (retrieved, excluded, duplicated, coded) on Pilot_Tally. Stratum targets and the cap are proposals; adjust before collecting and do not change them mid-pilot.

Sheet Pilot_Tally
A1: Pilot sampling and denominators
A2: Yellow cells are inputs (proposed pilot settings; change as needed). Everything else is computed from Sentiment_Coding, Search_Log and Reliability_Check.
A4: Pilot setting | B4: Value | C4: Note
A5: Max eligible comments per thread | B5: 10 | C5: Proposed cap so one viral thread cannot dominate; extra comments from a capped thread are not coded.
A6: Pilot size, minimum | B6: 50
A7: Pilot size, maximum | B7: 100
A8: Search test queries, minimum | B8: 8
A9: Search test queries, maximum | B9: 12
A10: Reliability subset, minimum | B10: 10
A11: Reliability subset, maximum | B11: 20
A13: Denominators | B13: Count | C13: Note
A14: Queries logged | B14: =COUNTA(Search_Log!$A$2:$A$201) -> 0 | C14: =IF(B14<B8,"below target",IF(B14>B9,"above target","within target")) -> below target
A15: Records logged | B15: =COUNTA(Sentiment_Coding!$A$2:$A$501) -> 0
A16: Excluded as irrelevant | B16: =COUNTIFS(Sentiment_Coding!$A$2:$A$501,"<>",Sentiment_Coding!$K$2:$K$501,"exclude") -> 0
A17: Uncertain relevance | B17: =COUNTIFS(Sentiment_Coding!$A$2:$A$501,"<>",Sentiment_Coding!$K$2:$K$501,"uncertain") -> 0 | C17: Resolve before analysis
A18: Duplicates flagged | B18: =COUNTIFS(Sentiment_Coding!$A$2:$A$501,"<>",Sentiment_Coding!$U$2:$U$501,1) -> 0
A19: Eligible coded records | B19: =COUNTIFS(Sentiment_Coding!$A$2:$A$501,"<>",Sentiment_Coding!$K$2:$K$501,"include",Sentiment_Coding!$U$2:$U$501,"<>1") -> 0 | C19: =IF(B19<B6,"below pilot minimum",IF(B19>B7,"above pilot maximum","within pilot range")) -> below pilot minimum
A20: Distinct threads among eligible | B20: =SUMPRODUCT((Sentiment_Coding!$F$2:$F$501<>"")*(Sentiment_Coding!$K$2:$K$501="include")*(Sentiment_Coding!$U$2:$U$501<>1)/(COUNTIFS(Sentiment_Coding!$F$2:$F$501,Sentiment_Coding!$F$2:$F$501&"",Sentiment_Coding!$K$2:$K$501,"include",Sentiment_Coding!$U$2:$U$501,"<>1")+1-(Sentiment_Coding!$F$2:$F$501<>"")*(Sentiment_Coding!$K$2:$K$501="include")*(Sentiment_Coding!$U$2:$U$501<>1))) -> 0
A21: Largest eligible comments in one thread | B21: =SUMPRODUCT(MAX((Sentiment_Coding!$F$2:$F$501<>"")*(Sentiment_Coding!$K$2:$K$501="include")*(Sentiment_Coding!$U$2:$U$501<>1)*COUNTIFS(Sentiment_Coding!$F$2:$F$501,Sentiment_Coding!$F$2:$F$501&"",Sentiment_Coding!$K$2:$K$501,"include",Sentiment_Coding!$U$2:$U$501,"<>1"))) -> 0 | C21: =IF(B21>B5,"CAP EXCEEDED: trim before analysis","ok") -> ok
A22: Records in reliability subset | B22: =COUNTA(Reliability_Check!$A$2:$A$201) -> 0 | C22: =IF(B22<B10,"below target",IF(B22>B11,"above target","within target")) -> below target
A24: Stratum | B24: Target eligible comments | C24: Eligible comments | D24: Distinct threads | E24: Share with accessibility_concern | F24: Share with aesthetic_dislike | G24: Status
A25: A_bills_jets_2015 | B25: 25 | C25: =COUNTIFS(Sentiment_Coding!$Z$2:$Z$501,$A25,Sentiment_Coding!$K$2:$K$501,"include",Sentiment_Coding!$U$2:$U$501,"<>1") -> 0 | D25: =SUMPRODUCT((Sentiment_Coding!$Z$2:$Z$501=$A25)*(Sentiment_Coding!$K$2:$K$501="include")*(Sentiment_Coding!$U$2:$U$501<>1)*(Sentiment_Coding!$F$2:$F$501<>"")/(COUNTIFS(Sentiment_Coding!$F$2:$F$501,Sentiment_Coding!$F$2:$F$501&"",Sentiment_Coding!$Z$2:$Z$501,$A25,Sentiment_Coding!$K$2:$K$501,"include",Sentiment_Coding!$U$2:$U$501,"<>1")+1-(Sentiment_Coding!$Z$2:$Z$501=$A25)*(Sentiment_Coding!$K$2:$K$501="include")*(Sentiment_Coding!$U$2:$U$501<>1)*(Sentiment_Coding!$F$2:$F$501<>""))) -> 0 | E25: =IF(C25=0,"",COUNTIFS(Sentiment_Coding!$Z$2:$Z$501,$A25,Sentiment_Coding!$K$2:$K$501,"include",Sentiment_Coding!$U$2:$U$501,"<>1",Sentiment_Coding!$N$2:$N$501,1)/C25) | F25: =IF(C25=0,"",COUNTIFS(Sentiment_Coding!$Z$2:$Z$501,$A25,Sentiment_Coding!$K$2:$K$501,"include",Sentiment_Coding!$U$2:$U$501,"<>1",Sentiment_Coding!$M$2:$M$501,1)/C25) | G25: =IF(C25>=B25,"target met","need "&(B25-C25)&" more") -> need 25 more
A26: B_other_games | B26: 35 | C26: =COUNTIFS(Sentiment_Coding!$Z$2:$Z$501,$A26,Sentiment_Coding!$K$2:$K$501,"include",Sentiment_Coding!$U$2:$U$501,"<>1") -> 0 | D26: =SUMPRODUCT((Sentiment_Coding!$Z$2:$Z$501=$A26)*(Sentiment_Coding!$K$2:$K$501="include")*(Sentiment_Coding!$U$2:$U$501<>1)*(Sentiment_Coding!$F$2:$F$501<>"")/(COUNTIFS(Sentiment_Coding!$F$2:$F$501,Sentiment_Coding!$F$2:$F$501&"",Sentiment_Coding!$Z$2:$Z$501,$A26,Sentiment_Coding!$K$2:$K$501,"include",Sentiment_Coding!$U$2:$U$501,"<>1")+1-(Sentiment_Coding!$Z$2:$Z$501=$A26)*(Sentiment_Coding!$K$2:$K$501="include")*(Sentiment_Coding!$U$2:$U$501<>1)*(Sentiment_Coding!$F$2:$F$501<>""))) -> 0 | E26: =IF(C26=0,"",COUNTIFS(Sentiment_Coding!$Z$2:$Z$501,$A26,Sentiment_Coding!$K$2:$K$501,"include",Sentiment_Coding!$U$2:$U$501,"<>1",Sentiment_Coding!$N$2:$N$501,1)/C26) | F26: =IF(C26=0,"",COUNTIFS(Sentiment_Coding!$Z$2:$Z$501,$A26,Sentiment_Coding!$K$2:$K$501,"include",Sentiment_Coding!$U$2:$U$501,"<>1",Sentiment_Coding!$M$2:$M$501,1)/C26) | G26: =IF(C26>=B26,"target met","need "&(B26-C26)&" more") -> need 35 more
A27: C_general_program | B27: 20 | C27: =COUNTIFS(Sentiment_Coding!$Z$2:$Z$501,$A27,Sentiment_Coding!$K$2:$K$501,"include",Sentiment_Coding!$U$2:$U$501,"<>1") -> 0 | D27: =SUMPRODUCT((Sentiment_Coding!$Z$2:$Z$501=$A27)*(Sentiment_Coding!$K$2:$K$501="include")*(Sentiment_Coding!$U$2:$U$501<>1)*(Sentiment_Coding!$F$2:$F$501<>"")/(COUNTIFS(Sentiment_Coding!$F$2:$F$501,Sentiment_Coding!$F$2:$F$501&"",Sentiment_Coding!$Z$2:$Z$501,$A27,Sentiment_Coding!$K$2:$K$501,"include",Sentiment_Coding!$U$2:$U$501,"<>1")+1-(Sentiment_Coding!$Z$2:$Z$501=$A27)*(Sentiment_Coding!$K$2:$K$501="include")*(Sentiment_Coding!$U$2:$U$501<>1)*(Sentiment_Coding!$F$2:$F$501<>""))) -> 0 | E27: =IF(C27=0,"",COUNTIFS(Sentiment_Coding!$Z$2:$Z$501,$A27,Sentiment_Coding!$K$2:$K$501,"include",Sentiment_Coding!$U$2:$U$501,"<>1",Sentiment_Coding!$N$2:$N$501,1)/C27) | F27: =IF(C27=0,"",COUNTIFS(Sentiment_Coding!$Z$2:$Z$501,$A27,Sentiment_Coding!$K$2:$K$501,"include",Sentiment_Coding!$U$2:$U$501,"<>1",Sentiment_Coding!$M$2:$M$501,1)/C27) | G27: =IF(C27>=B27,"target met","need "&(B27-C27)&" more") -> need 20 more
A28: Total | B28: =SUM(B25:B27) -> 80 | C28: =SUM(C25:C27) -> 0
A29: Stratum targets are proposed (A: Bills-Jets 2015, B: other Color Rush games 2015-2017, C: general program discussion). Eligible records with no stratum are not counted in rows 25-27.
A30: Pilot-size checks, thread cap and stratum shares are for pilot evaluation only. Shares from a pilot sample are not estimates of fan opinion.

Sheet Merchandise_Research
A1: date | B1: team | C1: player | D1: product_name | E1: retailer | F1: listed_price_usd | G1: sales_rank | H1: rank_source | I1: units_sold | J1: revenue_usd | K1: stock_status | L1: archived_url | M1: source_url | N1: quality_notes

Sheet Broadcast_Criticism
A1: date | B1: game | C1: broadcaster | D1: quote_or_summary | E1: criticism_type | F1: sentiment | G1: direct_quote | H1: publisher | I1: source_url | J1: notes
A2: 2018-04-10 | B2: Program-level, post-2017 | C2: Fox Sports (programming executive Bill Wanger, reported by Jason Barrett) | D2: Reportedly called the Color Rush uniforms a 'gimmick' that would not be needed to attract viewers in 2018. | E2: Program criticism (network executive, not an on-air announcer) | F2: negative | G2: 'gimmick' (reported single word) | H2: Awful Announcing | I2: https://www.thescore.com/news/1524879 | J2: Reported by Barrett Sports Media; NFL Network's Mike Garafolo noted the uniforms might remain as non-Thursday alternates. Not an on-air announcer.
A3: 2016 (fall; exact air date not shown in source) | B3: 2016-10-06 49ers-Cardinals (referenced) | C3: Al Michaels (NBC play-by-play), on HBO's Any Given Wednesday | D3: Criticized the Color Rush uniforms as a poor idea for Thursday games, saying he could not see the players' numbers in the 49ers-Cardinals game. | E3: On-air personality: uniform visibility and program criticism | F3: negative | G3: Color Rush uniforms? Excuse me? | H3: Awful Announcing | I3: https://awfulannouncing.com/2016/al-michaels-is-no-fan-of-thursday-night-football-especially-nfls-caca-color-rush.html | J3: Spoken in an interview, not during a broadcast. Tied to one game only loosely; counted once in the game log.

Sheet Accessibility_Audit
A1: game_id | B1: date | C1: home_team | D1: away_team | E1: uniform_combo_note | F1: uniform_verified | G1: home_uniform_desc | H1: away_uniform_desc | I1: home_jersey_hex | J1: away_jersey_hex | K1: field_color | L1: normal_contrast_score | M1: deuteranopia_contrast_score | N1: protanopia_contrast_score | O1: lowest_cvd_score | P1: conflict_flag | Q1: dE_normal | R1: dE_deuteranopia | S1: dE_protanopia | T1: score_confidence | U1: uniform_source_url | V1: method_or_simulator | W1: reviewer | X1: auditor_notes
A2: G01 | B2: =Game_Log_2015_2017!A2 -> 2015-11-12 | C2: =Game_Log_2015_2017!D2 -> New York Jets | D2: =Game_Log_2015_2017!E2 -> Buffalo Bills | E2: =Game_Log_2015_2017!I2 -> Bills red / Jets green | F2: yes | G2: Jets: Kelly green jersey, pants, socks and shoes; green chrome helmet logo/facemask | H2: Bills: scarlet red jersey, sleeves, pants, socks and shoes | O2: =IF(COUNT(M2:N2)=0,"",MIN(M2:N2)) | P2: =IF(O2="","",IF(O2<=2,1,0)) | U2: https://www.cbsnews.com/detroit/news/bright-and-bold-bills-jets-wearing-color-rush-uniforms | X2: Documented red-green problem; NFL later acknowledged its TV test missed color blindness (NPR).
A3: G02 | B3: =Game_Log_2015_2017!A3 -> 2015-11-19 | C3: =Game_Log_2015_2017!D3 -> Jacksonville Jaguars | D3: =Game_Log_2015_2017!E3 -> Tennessee Titans | E3: =Game_Log_2015_2017!I3 -> Titans blue / Jaguars gold | F3: yes | G3: Jaguars: all gold | H3: Titans: Titans blue (regular alternate) | O3: =IF(COUNT(M3:N3)=0,"",MIN(M3:N3)) | P3: =IF(O3="","",IF(O3<=2,1,0)) | U3: https://www.cbsnews.com/detroit/news/bright-and-bold-bills-jets-wearing-color-rush-uniforms
A4: G03 | B4: =Game_Log_2015_2017!A4 -> 2015-11-26 | C4: =Game_Log_2015_2017!D4 -> Dallas Cowboys | D4: =Game_Log_2015_2017!E4 -> Carolina Panthers | E4: =Game_Log_2015_2017!I4 -> Panthers blue / Cowboys white | F4: yes | G4: Cowboys: white 'Double Star' retro with white pants | H4: Panthers: Panthers blue (regular alternate, new Carolina blue pants) | O4: =IF(COUNT(M4:N4)=0,"",MIN(M4:N4)) | P4: =IF(O4="","",IF(O4<=2,1,0)) | U4: https://www.cbsnews.com/detroit/news/bright-and-bold-bills-jets-wearing-color-rush-uniforms ; https://en.wikipedia.org/wiki/Color_Rush
A5: G04 | B5: =Game_Log_2015_2017!A5 -> 2015-12-17 | C5: =Game_Log_2015_2017!D5 -> St. Louis Rams | D5: =Game_Log_2015_2017!E5 -> Tampa Bay Buccaneers | E5: =Game_Log_2015_2017!I5 -> Buccaneers red / Rams gold | F5: yes | G5: Rams: yellow-gold version of 1973-99 throwback | H5: Buccaneers: all red | O5: =IF(COUNT(M5:N5)=0,"",MIN(M5:N5)) | P5: =IF(O5="","",IF(O5<=2,1,0)) | U5: https://www.cbsnews.com/detroit/news/bright-and-bold-bills-jets-wearing-color-rush-uniforms
A6: G05 | B6: =Game_Log_2015_2017!A6 -> 2016-09-15 | C6: =Game_Log_2015_2017!D6 -> Buffalo Bills | D6: =Game_Log_2015_2017!E6 -> New York Jets | E6: =Game_Log_2015_2017!I6 -> Jets white instead of full green; Bills red | F6: yes | G6: Bills: all red | H6: Jets: mostly white uniform | O6: =IF(COUNT(M6:N6)=0,"",MIN(M6:N6)) | P6: =IF(O6="","",IF(O6<=2,1,0)) | U6: https://www.cbsnews.com/detroit/news/nfl-consults-with-colorblind-experts-on-color-rush-uniforms/ | X6: AP: NFL said it consulted color-blindness experts; Jets wore mostly white after the 2015 red-green complaints.
A7: G06 | B7: =Game_Log_2015_2017!A7 -> 2016-09-22 | C7: =Game_Log_2015_2017!D7 -> New England Patriots | D7: =Game_Log_2015_2017!E7 -> Houston Texans | E7: =Game_Log_2015_2017!I7 -> Texans / Patriots Color Rush | F7: partial | G7: Patriots: Color Rush (color not confirmed in sources reviewed) | H7: Texans: regular white, solid white socks | O7: =IF(COUNT(M7:N7)=0,"",MIN(M7:N7)) | P7: =IF(O7="","",IF(O7<=2,1,0)) | U7: https://en.wikipedia.org/wiki/Color_Rush
A8: G07 | B8: =Game_Log_2015_2017!A8 -> 2016-09-29 | C8: =Game_Log_2015_2017!D8 -> Cincinnati Bengals | D8: =Game_Log_2015_2017!E8 -> Miami Dolphins | E8: =Game_Log_2015_2017!I8 -> Dolphins / Bengals Color Rush | F8: partial | G8: Bengals: white Color Rush | H8: Dolphins: not described in sources reviewed | O8: =IF(COUNT(M8:N8)=0,"",MIN(M8:N8)) | P8: =IF(O8="","",IF(O8<=2,1,0)) | U8: https://en.wikipedia.org/wiki/Color_Rush
A9: G08 | B9: =Game_Log_2015_2017!A9 -> 2016-10-06 | C9: =Game_Log_2015_2017!D9 -> San Francisco 49ers | D9: =Game_Log_2015_2017!E9 -> Arizona Cardinals | E9: =Game_Log_2015_2017!I9 -> Cardinals / 49ers Color Rush | F9: partial | G9: 49ers: Color Rush (existing alternate uniform) | H9: Cardinals: regular white | O9: =IF(COUNT(M9:N9)=0,"",MIN(M9:N9)) | P9: =IF(O9="","",IF(O9<=2,1,0)) | U9: https://en.wikipedia.org/wiki/Color_Rush
A10: G09 | B10: =Game_Log_2015_2017!A10 -> 2016-10-13 | C10: =Game_Log_2015_2017!D10 -> San Diego Chargers | D10: =Game_Log_2015_2017!E10 -> Denver Broncos | E10: =Game_Log_2015_2017!I10 -> Broncos / Chargers Color Rush | O10: =IF(COUNT(M10:N10)=0,"",MIN(M10:N10)) | P10: =IF(O10="","",IF(O10<=2,1,0))
A11: G10 | B11: =Game_Log_2015_2017!A11 -> 2016-10-20 | C11: =Game_Log_2015_2017!D11 -> Green Bay Packers | D11: =Game_Log_2015_2017!E11 -> Chicago Bears | E11: =Game_Log_2015_2017!I11 -> Bears / Packers Color Rush | F11: partial | G11: Packers: all-white (home) | H11: Bears: blue jersey with blue pants | O11: =IF(COUNT(M11:N11)=0,"",MIN(M11:N11)) | P11: =IF(O11="","",IF(O11<=2,1,0)) | U11: https://en.wikipedia.org/wiki/Color_Rush
A12: G11 | B12: =Game_Log_2015_2017!A12 -> 2016-10-27 | C12: =Game_Log_2015_2017!D12 -> Tennessee Titans | D12: =Game_Log_2015_2017!E12 -> Jacksonville Jaguars | E12: =Game_Log_2015_2017!I12 -> Jaguars / Titans Color Rush | F12: partial | G12: Titans: head-to-toe light blue | H12: Jaguars: not described in sources reviewed | O12: =IF(COUNT(M12:N12)=0,"",MIN(M12:N12)) | P12: =IF(O12="","",IF(O12<=2,1,0)) | U12: https://www.tennesseetitans.com/news/titans-host-nfl-color-rush-game-oct-27-vs-jaguars-17676054
A13: G12 | B13: =Game_Log_2015_2017!A13 -> 2016-11-03 | C13: =Game_Log_2015_2017!D13 -> Tampa Bay Buccaneers | D13: =Game_Log_2015_2017!E13 -> Atlanta Falcons | E13: =Game_Log_2015_2017!I13 -> Falcons / Buccaneers Color Rush | F13: partial | G13: Buccaneers: Color Rush (2015 all-red design; not re-verified) | H13: Falcons: regular white | O13: =IF(COUNT(M13:N13)=0,"",MIN(M13:N13)) | P13: =IF(O13="","",IF(O13<=2,1,0)) | U13: https://en.wikipedia.org/wiki/Color_Rush
A14: G13 | B14: =Game_Log_2015_2017!A14 -> 2016-11-10 | C14: =Game_Log_2015_2017!D14 -> Baltimore Ravens | D14: =Game_Log_2015_2017!E14 -> Cleveland Browns | E14: =Game_Log_2015_2017!I14 -> Browns / Ravens Color Rush | F14: partial | G14: Ravens: Color Rush (not described in sources reviewed) | H14: Browns: regular white (brown-purple pairing avoided) | O14: =IF(COUNT(M14:N14)=0,"",MIN(M14:N14)) | P14: =IF(O14="","",IF(O14<=2,1,0)) | U14: https://en.wikipedia.org/wiki/Color_Rush
A15: G14 | B15: =Game_Log_2015_2017!A15 -> 2016-11-17 | C15: =Game_Log_2015_2017!D15 -> Carolina Panthers | D15: =Game_Log_2015_2017!E15 -> New Orleans Saints | E15: =Game_Log_2015_2017!I15 -> Saints / Panthers Color Rush | F15: partial | G15: Panthers: Color Rush (Panthers blue; not re-verified) | H15: Saints: white | O15: =IF(COUNT(M15:N15)=0,"",MIN(M15:N15)) | P15: =IF(O15="","",IF(O15<=2,1,0)) | U15: https://en.wikipedia.org/wiki/Color_Rush
A16: G15 | B16: =Game_Log_2015_2017!A16 -> 2016-12-01 | C16: =Game_Log_2015_2017!D16 -> Minnesota Vikings | D16: =Game_Log_2015_2017!E16 -> Dallas Cowboys | E16: =Game_Log_2015_2017!I16 -> Cowboys / Vikings Color Rush | F16: partial | G16: Vikings: Color Rush (not described in sources reviewed) | H16: Cowboys: white | O16: =IF(COUNT(M16:N16)=0,"",MIN(M16:N16)) | P16: =IF(O16="","",IF(O16<=2,1,0)) | U16: https://en.wikipedia.org/wiki/Color_Rush
A17: G16 | B17: =Game_Log_2015_2017!A17 -> 2016-12-08 | C17: =Game_Log_2015_2017!D17 -> Kansas City Chiefs | D17: =Game_Log_2015_2017!E17 -> Oakland Raiders | E17: =Game_Log_2015_2017!I17 -> Raiders / Chiefs Color Rush | F17: partial | G17: Chiefs: regular all-red set with red shoes | H17: Raiders: all-black alternate | O17: =IF(COUNT(M17:N17)=0,"",MIN(M17:N17)) | P17: =IF(O17="","",IF(O17<=2,1,0)) | U17: https://news.sportslogos.net/2016/09/13/all-32-nfl-teams-unveil-color-rush-uniforms/football/
A18: G17 | B18: =Game_Log_2015_2017!A18 -> 2016-12-15 | C18: =Game_Log_2015_2017!D18 -> Seattle Seahawks | D18: =Game_Log_2015_2017!E18 -> Los Angeles Rams | E18: =Game_Log_2015_2017!I18 -> Rams / Seahawks Color Rush | F18: partial | G18: Seahawks: Color Rush (not described in sources reviewed) | H18: Rams: regular white with white horns (yellow-green pairing avoided) | O18: =IF(COUNT(M18:N18)=0,"",MIN(M18:N18)) | P18: =IF(O18="","",IF(O18<=2,1,0)) | U18: https://en.wikipedia.org/wiki/Color_Rush
A19: G18 | B19: =Game_Log_2015_2017!A19 -> 2016-12-22 | C19: =Game_Log_2015_2017!D19 -> Philadelphia Eagles | D19: =Game_Log_2015_2017!E19 -> New York Giants | E19: =Game_Log_2015_2017!I19 -> Giants / Eagles Color Rush | F19: partial | G19: Eagles: existing alternate uniform | H19: Giants: all-white | O19: =IF(COUNT(M19:N19)=0,"",MIN(M19:N19)) | P19: =IF(O19="","",IF(O19<=2,1,0)) | U19: https://en.wikipedia.org/wiki/Color_Rush
A20: G19 | B20: =Game_Log_2015_2017!A20 -> 2017-09-14 | C20: =Game_Log_2015_2017!D20 -> Cincinnati Bengals | D20: =Game_Log_2015_2017!E20 -> Houston Texans | E20: =Game_Log_2015_2017!I20 -> Texans / Bengals Color Rush | F20: partial | G20: Bengals: white Color Rush | H20: Texans: not described in sources reviewed | O20: =IF(COUNT(M20:N20)=0,"",MIN(M20:N20)) | P20: =IF(O20="","",IF(O20<=2,1,0)) | U20: https://en.wikipedia.org/wiki/Color_Rush
A21: G20 | B21: =Game_Log_2015_2017!A21 -> 2017-09-21 | C21: =Game_Log_2015_2017!D21 -> San Francisco 49ers | D21: =Game_Log_2015_2017!E21 -> Los Angeles Rams | E21: =Game_Log_2015_2017!I21 -> Rams / 49ers Color Rush | O21: =IF(COUNT(M21:N21)=0,"",MIN(M21:N21)) | P21: =IF(O21="","",IF(O21<=2,1,0))
A22: G21 | B22: =Game_Log_2015_2017!A22 -> 2017-09-28 | C22: =Game_Log_2015_2017!D22 -> Green Bay Packers | D22: =Game_Log_2015_2017!E22 -> Chicago Bears | E22: =Game_Log_2015_2017!I22 -> Bears / Packers Color Rush | O22: =IF(COUNT(M22:N22)=0,"",MIN(M22:N22)) | P22: =IF(O22="","",IF(O22<=2,1,0))
A23: G22 | B23: =Game_Log_2015_2017!A23 -> 2017-10-05 | C23: =Game_Log_2015_2017!D23 -> Tampa Bay Buccaneers | D23: =Game_Log_2015_2017!E23 -> New England Patriots | E23: =Game_Log_2015_2017!I23 -> Patriots / Buccaneers Color Rush | F23: partial | G23: Buccaneers: not described in sources reviewed | H23: Patriots: regular away jersey with white pants and socks (one-time combination) | O23: =IF(COUNT(M23:N23)=0,"",MIN(M23:N23)) | P23: =IF(O23="","",IF(O23<=2,1,0)) | U23: https://en.wikipedia.org/wiki/Color_Rush
A24: G23 | B24: =Game_Log_2015_2017!A24 -> 2017-10-12 | C24: =Game_Log_2015_2017!D24 -> Carolina Panthers | D24: =Game_Log_2015_2017!E24 -> Philadelphia Eagles | E24: =Game_Log_2015_2017!I24 -> Eagles / Panthers Color Rush | O24: =IF(COUNT(M24:N24)=0,"",MIN(M24:N24)) | P24: =IF(O24="","",IF(O24<=2,1,0))
A25: G24 | B25: =Game_Log_2015_2017!A25 -> 2017-10-19 | C25: =Game_Log_2015_2017!D25 -> Oakland Raiders | D25: =Game_Log_2015_2017!E25 -> Kansas City Chiefs | E25: =Game_Log_2015_2017!I25 -> Chiefs / Raiders Color Rush | O25: =IF(COUNT(M25:N25)=0,"",MIN(M25:N25)) | P25: =IF(O25="","",IF(O25<=2,1,0))
A26: G25 | B26: =Game_Log_2015_2017!A26 -> 2017-10-26 | C26: =Game_Log_2015_2017!D26 -> Baltimore Ravens | D26: =Game_Log_2015_2017!E26 -> Miami Dolphins | E26: =Game_Log_2015_2017!I26 -> Dolphins / Ravens Color Rush | O26: =IF(COUNT(M26:N26)=0,"",MIN(M26:N26)) | P26: =IF(O26="","",IF(O26<=2,1,0))
A27: G26 | B27: =Game_Log_2015_2017!A27 -> 2017-11-02 | C27: =Game_Log_2015_2017!D27 -> New York Jets | D27: =Game_Log_2015_2017!E27 -> Buffalo Bills | E27: =Game_Log_2015_2017!I27 -> Bills / Jets Color Rush | F27: yes | G27: Jets: all green | H27: Bills: all white | O27: =IF(COUNT(M27:N27)=0,"",MIN(M27:N27)) | P27: =IF(O27="","",IF(O27<=2,1,0)) | U27: https://abc7ny.com/2596929 | X27: Red-green pairing avoided (ESPN, Nov 2, 2017).
